Workbook

Sheet README
A1: KMC Worksheet — companion to Supplementary Material S1
A2: Implements the calibration (Table 11) and the headroom procedure (Table 6) of the paper with spreadsheet formulas.
A4: How to use
A5: 1. Calib_Hazard: enter the K assessed before each past integrated test, its cost and its outcome. The sheet fits the test hazard by likelihood and combines it with a public prior.
A6: 2. Calib_Rates: enter campaign data (cost vs K or M) and plateaus. The sheet fits the three rates and the two ceilings.
A7: 3. Parameters: calibrated values flow in automatically (green). Type a value in the Override column to use a rounded or prior value instead. Set the target, exposure limit and test cost.
A8: 4. Decision: at each review, enter cumulative cost, K and M. The sheet computes the ceilings, rates, hazards, net knowledge rates and the recommended next activity.
A10: Colour code
A11: Blue text on yellow: inputs you edit. Black: formulas. Green: values linked from another sheet.
A13: Example data
A14: All example data belong to the fictional organization 'Org X' of Supplementary Material S1 (Rocket R, engine E-1, Project N). Replace them with your own records.
A16: Limits
A17: The sheet applies the observable procedure. The optimal policy, the exact derivative D_a and Monte Carlo checks need the Python code (kmc_model.py).

Sheet Calib_Hazard
A1: Test hazard λ_T: likelihood of past integrated tests + public prior (S1, Sec. 3.1–3.2)
A3: Prior median λ (per BU) | B3: 0.9 | C3: FAA first flights 1980–2002 (paper, Sec. VI-B)
A4: Prior σ of ln λ | B4: 0.5 | C4: assumed spread of the prior
A6: Test n | B6: K before test | C6: Test cost c_f (BU) | D6: Outcome (1 = failure/shock, 0 = success) | E6: x = (1−K)²·c_f | F6: failure flag | G6: success flag | H6: ΔK to next test | I6: (1−K)·c_f | J6: ΔK·(1−K)c_f | K6: ((1−K)c_f)² | N6: λ grid | O6: log-likelihood | P6: log-prior | Q6: log-posterior (shifted) | R6: posterior weight | S6: cumulative
A7: 1 | B7: 0.1 | C7: 2 | D7: 1 | E7: =IF(B7="",0,(1-B7)^2*C7) -> 1.62 | F7: =IF(B7="",0,IF(D7=1,1,0)) -> 1 | G7: =IF(B7="",0,IF(D7=0,1,0)) -> 0 | H7: =IF(OR(B7="",B8=""),0,B8-B7) -> 0.06 | I7: =IF(OR(B7="",B8=""),0,(1-B7)*C7) -> 1.8 | J7: =H7*I7 -> 0.108 | K7: =I7^2 -> 3.24 | N7: 0.05 | O7: =SUMPRODUCT($F$7:$F$26,LN(1-EXP(-N7*$E$7:$E$26)+0.000000000001))-N7*SUMPRODUCT($G$7:$G$26,$E$7:$E$26) -> -20.783782 | P7: =-0.5*((LN(N7)-LN($B$3))/$B$4)^2-LN(N7) -> -13.712766 | Q7: =O7+P7 -> -34.496547 | R7: =EXP(Q7-MAX($Q$7:$Q$506)) -> 3.164246e-14 | S7: =SUM($R$7:R7)/SUM($R$7:$R$506) -> 2.4794996e-16
A8: 2 | B8: 0.16 | C8: 2 | D8: 1 | E8: =IF(B8="",0,(1-B8)^2*C8) -> 1.4112 | F8: =IF(B8="",0,IF(D8=1,1,0)) -> 1 | G8: =IF(B8="",0,IF(D8=0,1,0)) -> 0 | H8: =IF(OR(B8="",B9=""),0,B9-B8) -> 0.05 | I8: =IF(OR(B8="",B9=""),0,(1-B8)*C8) -> 1.68 | J8: =H8*I8 -> 0.084 | K8: =I8^2 -> 2.8224 | N8: =N7+0.01 -> 0.06 | O8: =SUMPRODUCT($F$7:$F$26,LN(1-EXP(-N8*$E$7:$E$26)+0.000000000001))-N8*SUMPRODUCT($G$7:$G$26,$E$7:$E$26) -> -19.551408 | P8: =-0.5*((LN(N8)-LN($B$3))/$B$4)^2-LN(N8) -> -11.853661 | Q8: =O8+P8 -> -31.405069 | R8: =EXP(Q8-MAX($Q$7:$Q$506)) -> 6.964375e-13 | S8: =SUM($R$7:R8)/SUM($R$7:$R$506) -> 5.7052264e-15
A9: 3 | B9: 0.21 | C9: 2 | D9: 1 | E9: =IF(B9="",0,(1-B9)^2*C9) -> 1.2482 | F9: =IF(B9="",0,IF(D9=1,1,0)) -> 1 | G9: =IF(B9="",0,IF(D9=0,1,0)) -> 0 | H9: =IF(OR(B9="",B10=""),0,B10-B9) -> 0.06 | I9: =IF(OR(B9="",B10=""),0,(1-B9)*C9) -> 1.58 | J9: =H9*I9 -> 0.0948 | K9: =I9^2 -> 2.4964 | N9: =N8+0.01 -> 0.07 | O9: =SUMPRODUCT($F$7:$F$26,LN(1-EXP(-N9*$E$7:$E$26)+0.000000000001))-N9*SUMPRODUCT($G$7:$G$26,$E$7:$E$26) -> -18.516153 | P9: =-0.5*((LN(N9)-LN($B$3))/$B$4)^2-LN(N9) -> -10.385545 | Q9: =O9+P9 -> -28.901699 | R9: =EXP(Q9-MAX($Q$7:$Q$506)) -> 8.5129878e-12 | S9: =SUM($R$7:R9)/SUM($R$7:$R$506) -> 7.2412903e-14
A10: 4 | B10: 0.27 | C10: 2 | D10: 1 | E10: =IF(B10="",0,(1-B10)^2*C10) -> 1.0658 | F10: =IF(B10="",0,IF(D10=1,1,0)) -> 1 | G10: =IF(B10="",0,IF(D10=0,1,0)) -> 0 | H10: =IF(OR(B10="",B11=""),0,B11-B10) -> 0.05 | I10: =IF(OR(B10="",B11=""),0,(1-B10)*C10) -> 1.46 | J10: =H10*I10 -> 0.073 | K10: =I10^2 -> 2.1316 | N10: =N9+0.01 -> 0.08 | O10: =SUMPRODUCT($F$7:$F$26,LN(1-EXP(-N10*$E$7:$E$26)+0.000000000001))-N10*SUMPRODUCT($G$7:$G$26,$E$7:$E$26) -> -17.625157 | P10: =-0.5*((LN(N10)-LN($B$3))/$B$4)^2-LN(N10) -> -9.1906351 | Q10: =O10+P10 -> -26.815792 | R10: =EXP(Q10-MAX($Q$7:$Q$506)) -> 6.8545654e-11 | S10: =SUM($R$7:R10)/SUM($R$7:$R$506) -> 6.0953588e-13
A11: 5 | B11: 0.32 | C11: 2 | D11: 1 | E11: =IF(B11="",0,(1-B11)^2*C11) -> 0.9248 | F11: =IF(B11="",0,IF(D11=1,1,0)) -> 1 | G11: =IF(B11="",0,IF(D11=0,1,0)) -> 0 | H11: =IF(OR(B11="",B12=""),0,B12-B11) -> 0.05 | I11: =IF(OR(B11="",B12=""),0,(1-B11)*C11) -> 1.36 | J11: =H11*I11 -> 0.068 | K11: =I11^2 -> 1.8496 | N11: =N10+0.01 -> 0.09 | O11: =SUMPRODUCT($F$7:$F$26,LN(1-EXP(-N11*$E$7:$E$26)+0.000000000001))-N11*SUMPRODUCT($G$7:$G$26,$E$7:$E$26) -> -16.844321 | P11: =-0.5*((LN(N11)-LN($B$3))/$B$4)^2-LN(N11) -> -8.1958506 | Q11: =O11+P11 -> -25.040172 | R11: =EXP(Q11-MAX($Q$7:$Q$506)) -> 4.0468932e-10 | S11: =SUM($R$7:R11)/SUM($R$7:$R$506) -> 3.7806769e-12
A12: 6 | B12: 0.37 | C12: 2 | D12: 1 | E12: =IF(B12="",0,(1-B12)^2*C12) -> 0.7938 | F12: =IF(B12="",0,IF(D12=1,1,0)) -> 1 | G12: =IF(B12="",0,IF(D12=0,1,0)) -> 0 | H12: =IF(OR(B12="",B13=""),0,B13-B12) -> 0.05 | I12: =IF(OR(B12="",B13=""),0,(1-B12)*C12) -> 1.26 | J12: =H12*I12 -> 0.063 | K12: =I12^2 -> 1.5876 | N12: =N11+0.01 -> 0.1 | O12: =SUMPRODUCT($F$7:$F$26,LN(1-EXP(-N12*$E$7:$E$26)+0.000000000001))-N12*SUMPRODUCT($G$7:$G$26,$E$7:$E$26) -> -16.150367 | P12: =-0.5*((LN(N12)-LN($B$3))/$B$4)^2-LN(N12) -> -7.3530066 | Q12: =O12+P12 -> -23.503373 | R12: =EXP(Q12-MAX($Q$7:$Q$506)) -> 1.8816762e-09 | S12: =SUM($R$7:R12)/SUM($R$7:$R$506) -> 1.852547e-11
A13: 7 | B13: 0.42 | C13: 2 | D13: 1 | E13: =IF(B13="",0,(1-B13)^2*C13) -> 0.6728 | F13: =IF(B13="",0,IF(D13=1,1,0)) -> 1 | G13: =IF(B13="",0,IF(D13=0,1,0)) -> 0 | H13: =IF(OR(B13="",B14=""),0,B14-B13) -> 0.05 | I13: =IF(OR(B13="",B14=""),0,(1-B13)*C13) -> 1.16 | J13: =H13*I13 -> 0.058 | K13: =I13^2 -> 1.3456 | N13: =N12+0.01 -> 0.11 | O13: =SUMPRODUCT($F$7:$F$26,LN(1-EXP(-N13*$E$7:$E$26)+0.000000000001))-N13*SUMPRODUCT($G$7:$G$26,$E$7:$E$26) -> -15.526688 | P13: =-0.5*((LN(N13)-LN($B$3))/$B$4)^2-LN(N13) -> -6.6288134 | Q13: =O13+P13 -> -22.155501 | R13: =EXP(Q13-MAX($Q$7:$Q$506)) -> 7.2429992e-09 | S13: =SUM($R$7:R13)/SUM($R$7:$R$506) -> 7.5281531e-11
A14: 8 | B14: 0.47 | C14: 2 | D14: 0 | E14: =IF(B14="",0,(1-B14)^2*C14) -> 0.5618 | F14: =IF(B14="",0,IF(D14=1,1,0)) -> 0 | G14: =IF(B14="",0,IF(D14=0,1,0)) -> 1 | H14: =IF(OR(B14="",B15=""),0,B15-B14) -> 0 | I14: =IF(OR(B14="",B15=""),0,(1-B14)*C14) -> 0 | J14: =H14*I14 -> 0 | K14: =I14^2 -> 0 | N14: =N13+0.01 -> 0.12 | O14: =SUMPRODUCT($F$7:$F$26,LN(1-EXP(-N14*$E$7:$E$26)+0.000000000001))-N14*SUMPRODUCT($G$7:$G$26,$E$7:$E$26) -> -14.961023 | P14: =-0.5*((LN(N14)-LN($B$3))/$B$4)^2-LN(N14) -> -5.9994048 | Q14: =O14+P14 -> -20.960428 | R14: =EXP(Q14-MAX($Q$7:$Q$506)) -> 2.3929415e-08 | S14: =SUM($R$7:R14)/SUM($R$7:$R$506) -> 2.6279216e-10
A15: 9 | E15: =IF(B15="",0,(1-B15)^2*C15) -> 0 | F15: =IF(B15="",0,IF(D15=1,1,0)) -> 0 | G15: =IF(B15="",0,IF(D15=0,1,0)) -> 0 | H15: =IF(OR(B15="",B16=""),0,B16-B15) -> 0 | I15: =IF(OR(B15="",B16=""),0,(1-B15)*C15) -> 0 | J15: =H15*I15 -> 0 | K15: =I15^2 -> 0 | N15: =N14+0.01 -> 0.13 | O15: =SUMPRODUCT($F$7:$F$26,LN(1-EXP(-N15*$E$7:$E$26)+0.000000000001))-N15*SUMPRODUCT($G$7:$G$26,$E$7:$E$26) -> -14.444062 | P15: =-0.5*((LN(N15)-LN($B$3))/$B$4)^2-LN(N15) -> -5.447148 | Q15: =O15+P15 -> -19.89121 | R15: =EXP(Q15-MAX($Q$7:$Q$506)) -> 6.9708767e-08 | S15: =SUM($R$7:R15)/SUM($R$7:$R$506) -> 8.0902928e-10
A16: 10 | E16: =IF(B16="",0,(1-B16)^2*C16) -> 0 | F16: =IF(B16="",0,IF(D16=1,1,0)) -> 0 | G16: =IF(B16="",0,IF(D16=0,1,0)) -> 0 | H16: =IF(OR(B16="",B17=""),0,B17-B16) -> 0 | I16: =IF(OR(B16="",B17=""),0,(1-B16)*C16) -> 0 | J16: =H16*I16 -> 0 | K16: =I16^2 -> 0 | N16: =N15+0.01 -> 0.14 | O16: =SUMPRODUCT($F$7:$F$26,LN(1-EXP(-N16*$E$7:$E$26)+0.000000000001))-N16*SUMPRODUCT($G$7:$G$26,$E$7:$E$26) -> -13.968568 | P16: =-0.5*((LN(N16)-LN($B$3))/$B$4)^2-LN(N16) -> -4.9586857 | Q16: =O16+P16 -> -18.927253 | R16: =EXP(Q16-MAX($Q$7:$Q$506)) -> 1.8277997e-07 | S16: =SUM($R$7:R16)/SUM($R$7:$R$506) -> 2.2412911e-09
A17: 11 | E17: =IF(B17="",0,(1-B17)^2*C17) -> 0 | F17: =IF(B17="",0,IF(D17=1,1,0)) -> 0 | G17: =IF(B17="",0,IF(D17=0,1,0)) -> 0 | H17: =IF(OR(B17="",B18=""),0,B18-B17) -> 0 | I17: =IF(OR(B17="",B18=""),0,(1-B17)*C17) -> 0 | J17: =H17*I17 -> 0 | K17: =I17^2 -> 0 | N17: =N16+0.01 -> 0.15 | O17: =SUMPRODUCT($F$7:$F$26,LN(1-EXP(-N17*$E$7:$E$26)+0.000000000001))-N17*SUMPRODUCT($G$7:$G$26,$E$7:$E$26) -> -13.528802 | P17: =-0.5*((LN(N17)-LN($B$3))/$B$4)^2-LN(N17) -> -4.523684 | Q17: =O17+P17 -> -18.052486 | R17: =EXP(Q17-MAX($Q$7:$Q$506)) -> 4.3836445e-07 | S17: =SUM($R$7:R17)/SUM($R$7:$R$506) -> 5.67631e-09
A18: 12 | E18: =IF(B18="",0,(1-B18)^2*C18) -> 0 | F18: =IF(B18="",0,IF(D18=1,1,0)) -> 0 | G18: =IF(B18="",0,IF(D18=0,1,0)) -> 0 | H18: =IF(OR(B18="",B19=""),0,B19-B18) -> 0 | I18: =IF(OR(B18="",B19=""),0,(1-B18)*C18) -> 0 | J18: =H18*I18 -> 0 | K18: =I18^2 -> 0 | N18: =N17+0.01 -> 0.16 | O18: =SUMPRODUCT($F$7:$F$26,LN(1-EXP(-N18*$E$7:$E$26)+0.000000000001))-N18*SUMPRODUCT($G$7:$G$26,$E$7:$E$26) -> -13.120139 | P18: =-0.5*((LN(N18)-LN($B$3))/$B$4)^2-LN(N18) -> -4.1340029 | Q18: =O18+P18 -> -17.254142 | R18: =EXP(Q18-MAX($Q$7:$Q$506)) -> 9.7398319e-07 | S18: =SUM($R$7:R18)/SUM($R$7:$R$506) -> 1.3308431e-08
A19: 13 | E19: =IF(B19="",0,(1-B19)^2*C19) -> 0 | F19: =IF(B19="",0,IF(D19=1,1,0)) -> 0 | G19: =IF(B19="",0,IF(D19=0,1,0)) -> 0 | H19: =IF(OR(B19="",B20=""),0,B20-B19) -> 0 | I19: =IF(OR(B19="",B20=""),0,(1-B19)*C19) -> 0 | J19: =H19*I19 -> 0 | K19: =I19^2 -> 0 | N19: =N18+0.01 -> 0.17 | O19: =SUMPRODUCT($F$7:$F$26,LN(1-EXP(-N19*$E$7:$E$26)+0.000000000001))-N19*SUMPRODUCT($G$7:$G$26,$E$7:$E$26) -> -12.738797 | P19: =-0.5*((LN(N19)-LN($B$3))/$B$4)^2-LN(N19) -> -3.7831298 | Q19: =O19+P19 -> -16.521927 | R19: =EXP(Q19-MAX($Q$7:$Q$506)) -> 2.0255755e-06 | S19: =SUM($R$7:R19)/SUM($R$7:$R$506) -> 2.9180818e-08
A20: 14 | E20: =IF(B20="",0,(1-B20)^2*C20) -> 0 | F20: =IF(B20="",0,IF(D20=1,1,0)) -> 0 | G20: =IF(B20="",0,IF(D20=0,1,0)) -> 0 | H20: =IF(OR(B20="",B21=""),0,B21-B20) -> 0 | I20: =IF(OR(B20="",B21=""),0,(1-B20)*C20) -> 0 | J20: =H20*I20 -> 0 | K20: =I20^2 -> 0 | N20: =N19+0.01 -> 0.18 | O20: =SUMPRODUCT($F$7:$F$26,LN(1-EXP(-N20*$E$7:$E$26)+0.000000000001))-N20*SUMPRODUCT($G$7:$G$26,$E$7:$E$26) -> -12.381642 | P20: =-0.5*((LN(N20)-LN($B$3))/$B$4)^2-LN(N20) -> -3.4657824 | Q20: =O20+P20 -> -15.847424 | R20: =EXP(Q20-MAX($Q$7:$Q$506)) -> 3.9763195e-06 | S20: =SUM($R$7:R20)/SUM($R$7:$R$506) -> 6.0339213e-08
A21: 15 | E21: =IF(B21="",0,(1-B21)^2*C21) -> 0 | F21: =IF(B21="",0,IF(D21=1,1,0)) -> 0 | G21: =IF(B21="",0,IF(D21=0,1,0)) -> 0 | H21: =IF(OR(B21="",B22=""),0,B22-B21) -> 0 | I21: =IF(OR(B21="",B22=""),0,(1-B21)*C21) -> 0 | J21: =H21*I21 -> 0 | K21: =I21^2 -> 0 | N21: =N20+0.01 -> 0.19 | O21: =SUMPRODUCT($F$7:$F$26,LN(1-EXP(-N21*$E$7:$E$26)+0.000000000001))-N21*SUMPRODUCT($G$7:$G$26,$E$7:$E$26) -> -12.046048 | P21: =-0.5*((LN(N21)-LN($B$3))/$B$4)^2-LN(N21) -> -3.1776248 | Q21: =O21+P21 -> -15.223673 | R21: =EXP(Q21-MAX($Q$7:$Q$506)) -> 7.4194735e-06 | S21: =SUM($R$7:R21)/SUM($R$7:$R$506) -> 1.1847812e-07
A22: 16 | E22: =IF(B22="",0,(1-B22)^2*C22) -> 0 | F22: =IF(B22="",0,IF(D22=1,1,0)) -> 0 | G22: =IF(B22="",0,IF(D22=0,1,0)) -> 0 | H22: =IF(OR(B22="",B23=""),0,B23-B22) -> 0 | I22: =IF(OR(B22="",B23=""),0,(1-B22)*C22) -> 0 | J22: =H22*I22 -> 0 | K22: =I22^2 -> 0 | N22: =N21+0.01 -> 0.2 | O22: =SUMPRODUCT($F$7:$F$26,LN(1-EXP(-N22*$E$7:$E$26)+0.000000000001))-N22*SUMPRODUCT($G$7:$G$26,$E$7:$E$26) -> -11.729795 | P22: =-0.5*((LN(N22)-LN($B$3))/$B$4)^2-LN(N22) -> -2.9150597 | Q22: =O22+P22 -> -14.644855 | R22: =EXP(Q22-MAX($Q$7:$Q$506)) -> 1.3235814e-05 | S22: =SUM($R$7:R22)/SUM($R$7:$R$506) -> 2.2219382e-07
A23: 17 | E23: =IF(B23="",0,(1-B23)^2*C23) -> 0 | F23: =IF(B23="",0,IF(D23=1,1,0)) -> 0 | G23: =IF(B23="",0,IF(D23=0,1,0)) -> 0 | H23: =IF(OR(B23="",B24=""),0,B24-B23) -> 0 | I23: =IF(OR(B23="",B24=""),0,(1-B23)*C23) -> 0 | J23: =H23*I23 -> 0 | K23: =I23^2 -> 0 | N23: =N22+0.01 -> 0.21 | O23: =SUMPRODUCT($F$7:$F$26,LN(1-EXP(-N23*$E$7:$E$26)+0.000000000001))-N23*SUMPRODUCT($G$7:$G$26,$E$7:$E$26) -> -11.430987 | P23: =-0.5*((LN(N23)-LN($B$3))/$B$4)^2-LN(N23) -> -2.6750741 | Q23: =O23+P23 -> -14.106061 | R23: =EXP(Q23-MAX($Q$7:$Q$506)) -> 2.2685366e-05 | S23: =SUM($R$7:R23)/SUM($R$7:$R$506) -> 3.9995609e-07
A24: 18 | E24: =IF(B24="",0,(1-B24)^2*C24) -> 0 | F24: =IF(B24="",0,IF(D24=1,1,0)) -> 0 | G24: =IF(B24="",0,IF(D24=0,1,0)) -> 0 | H24: =IF(OR(B24="",B25=""),0,B25-B24) -> 0 | I24: =IF(OR(B24="",B25=""),0,(1-B24)*C24) -> 0 | J24: =H24*I24 -> 0 | K24: =I24^2 -> 0 | N24: =N23+0.01 -> 0.22 | O24: =SUMPRODUCT($F$7:$F$26,LN(1-EXP(-N24*$E$7:$E$26)+0.000000000001))-N24*SUMPRODUCT($G$7:$G$26,$E$7:$E$26) -> -11.147993 | P24: =-0.5*((LN(N24)-LN($B$3))/$B$4)^2-LN(N24) -> -2.4551224 | Q24: =O24+P24 -> -13.603116 | R24: =EXP(Q24-MAX($Q$7:$Q$506)) -> 3.7512176e-05 | S24: =SUM($R$7:R24)/SUM($R$7:$R$506) -> 6.9390108e-07
A25: 19 | E25: =IF(B25="",0,(1-B25)^2*C25) -> 0 | F25: =IF(B25="",0,IF(D25=1,1,0)) -> 0 | G25: =IF(B25="",0,IF(D25=0,1,0)) -> 0 | H25: =IF(OR(B25="",B26=""),0,B26-B25) -> 0 | I25: =IF(OR(B25="",B26=""),0,(1-B25)*C25) -> 0 | J25: =H25*I25 -> 0 | K25: =I25^2 -> 0 | N25: =N24+0.01 -> 0.23 | O25: =SUMPRODUCT($F$7:$F$26,LN(1-EXP(-N25*$E$7:$E$26)+0.000000000001))-N25*SUMPRODUCT($G$7:$G$26,$E$7:$E$26) -> -10.8794 | P25: =-0.5*((LN(N25)-LN($B$3))/$B$4)^2-LN(N25) -> -2.2530373 | Q25: =O25+P25 -> -13.132438 | R25: =EXP(Q25-MAX($Q$7:$Q$506)) -> 6.0059962e-05 | S25: =SUM($R$7:R25)/SUM($R$7:$R$506) -> 1.1645303e-06
A26: 20 | E26: =IF(B26="",0,(1-B26)^2*C26) -> 0 | F26: =IF(B26="",0,IF(D26=1,1,0)) -> 0 | G26: =IF(B26="",0,IF(D26=0,1,0)) -> 0 | H26: 0 | I26: 0 | J26: =H26*I26 -> 0 | K26: =I26^2 -> 0 | N26: =N25+0.01 -> 0.24 | O26: =SUMPRODUCT($F$7:$F$26,LN(1-EXP(-N26*$E$7:$E$26)+0.000000000001))-N26*SUMPRODUCT($G$7:$G$26,$E$7:$E$26) -> -10.623976 | P26: =-0.5*((LN(N26)-LN($B$3))/$B$4)^2-LN(N26) -> -2.0669606 | Q26: =O26+P26 -> -12.690937 | R26: =EXP(Q26-MAX($Q$7:$Q$506)) -> 9.3395636e-05 | S26: =SUM($R$7:R26)/SUM($R$7:$R$506) -> 1.8963774e-06
N27: =N26+0.01 -> 0.25 | O27: =SUMPRODUCT($F$7:$F$26,LN(1-EXP(-N27*$E$7:$E$26)+0.000000000001))-N27*SUMPRODUCT($G$7:$G$26,$E$7:$E$26) -> -10.380638 | P27: =-0.5*((LN(N27)-LN($B$3))/$B$4)^2-LN(N27) -> -1.8952887 | Q27: =O27+P27 -> -12.275927 | R27: =EXP(Q27-MAX($Q$7:$Q$506)) -> 0.000141437 | S27: =SUM($R$7:R27)/SUM($R$7:$R$506) -> 3.0046762e-06
N28: =N27+0.01 -> 0.26 | O28: =SUMPRODUCT($F$7:$F$26,LN(1-EXP(-N28*$E$7:$E$26)+0.000000000001))-N28*SUMPRODUCT($G$7:$G$26,$E$7:$E$26) -> -10.148433 | P28: =-0.5*((LN(N28)-LN($B$3))/$B$4)^2-LN(N28) -> -1.7366294 | Q28: =O28+P28 -> -11.885062 | R28: =EXP(Q28-MAX($Q$7:$Q$506)) -> 0.00020908048 | S28: =SUM($R$7:R28)/SUM($R$7:$R$506) -> 4.6430285e-06
A29: Results | N29: =N28+0.01 -> 0.27 | O29: =SUMPRODUCT($F$7:$F$26,LN(1-EXP(-N29*$E$7:$E$26)+0.000000000001))-N29*SUMPRODUCT($G$7:$G$26,$E$7:$E$26) -> -9.9265131 | P29: =-0.5*((LN(N29)-LN($B$3))/$B$4)^2-LN(N29) -> -1.5897677 | Q29: =O29+P29 -> -11.516281 | R29: =EXP(Q29-MAX($Q$7:$Q$506)) -> 0.00030232431 | S29: =SUM($R$7:R29)/SUM($R$7:$R$506) -> 7.0120384e-06
A30: λ_T, data only (maximum likelihood) | B30: =INDEX(N$7:N$506,MATCH(MAX(O$7:O$506),O$7:O$506,0)) -> 2.55 | N30: =N29+0.01 -> 0.28 | O30: =SUMPRODUCT($F$7:$F$26,LN(1-EXP(-N30*$E$7:$E$26)+0.000000000001))-N30*SUMPRODUCT($G$7:$G$26,$E$7:$E$26) -> -9.7141259 | P30: =-0.5*((LN(N30)-LN($B$3))/$B$4)^2-LN(N30) -> -1.4536379 | Q30: =O30+P30 -> -11.167764 | R30: =EXP(Q30-MAX($Q$7:$Q$506)) -> 0.00042838285 | S30: =SUM($R$7:R30)/SUM($R$7:$R$506) -> 1.0368842e-05
A31: λ_T, posterior median (use this) | B31: =INDEX(N$7:N$506,MATCH(0.5,S$7:S$506,1)+1) -> 1.48 | N31: =N30+0.01 -> 0.29 | O31: =SUMPRODUCT($F$7:$F$26,LN(1-EXP(-N31*$E$7:$E$26)+0.000000000001))-N31*SUMPRODUCT($G$7:$G$26,$E$7:$E$26) -> -9.5105964 | P31: =-0.5*((LN(N31)-LN($B$3))/$B$4)^2-LN(N31) -> -1.3273008 | Q31: =O31+P31 -> -10.837897 | R31: =EXP(Q31-MAX($Q$7:$Q$506)) -> 0.00059578742 | S31: =SUM($R$7:R31)/SUM($R$7:$R$506) -> 1.5037425e-05
A32: posterior 5th percentile | B32: =INDEX(N$7:N$506,MATCH(0.05,S$7:S$506,1)+1) -> 0.8 | N32: =N31+0.01 -> 0.3 | O32: =SUMPRODUCT($F$7:$F$26,LN(1-EXP(-N32*$E$7:$E$26)+0.000000000001))-N32*SUMPRODUCT($G$7:$G$26,$E$7:$E$26) -> -9.3153187 | P32: =-0.5*((LN(N32)-LN($B$3))/$B$4)^2-LN(N32) -> -1.2099251 | Q32: =O32+P32 -> -10.525244 | R32: =EXP(Q32-MAX($Q$7:$Q$506)) -> 0.00081446975 | S32: =SUM($R$7:R32)/SUM($R$7:$R$506) -> 2.1419601e-05
A33: posterior 95th percentile | B33: =INDEX(N$7:N$506,MATCH(0.95,S$7:S$506,1)+1) -> 2.68 | N33: =N32+0.01 -> 0.31 | O33: =SUMPRODUCT($F$7:$F$26,LN(1-EXP(-N33*$E$7:$E$26)+0.000000000001))-N33*SUMPRODUCT($G$7:$G$26,$E$7:$E$26) -> -9.1277467 | P33: =-0.5*((LN(N33)-LN($B$3))/$B$4)^2-LN(N33) -> -1.1007721 | Q33: =O33+P33 -> -10.228519 | R33: =EXP(Q33-MAX($Q$7:$Q$506)) -> 0.0010958245 | S33: =SUM($R$7:R33)/SUM($R$7:$R$506) -> 3.000647e-05
A34: e_T, knowledge per BU of integrated testing | B34: =IF(SUM(K7:K26)=0,"",SUM(J7:J26)/SUM(K7:K26)) -> 0.035467777 | N34: =N33+0.01 -> 0.32 | O34: =SUMPRODUCT($F$7:$F$26,LN(1-EXP(-N34*$E$7:$E$26)+0.000000000001))-N34*SUMPRODUCT($G$7:$G$26,$E$7:$E$26) -> -8.9473861 | P34: =-0.5*((LN(N34)-LN($B$3))/$B$4)^2-LN(N34) -> -0.99918283 | Q34: =O34+P34 -> -9.946569 | R34: =EXP(Q34-MAX($Q$7:$Q$506)) -> 0.0014527479 | S34: =SUM($R$7:R34)/SUM($R$7:$R$506) -> 4.1390186e-05
N35: =N34+0.01 -> 0.33 | O35: =SUMPRODUCT($F$7:$F$26,LN(1-EXP(-N35*$E$7:$E$26)+0.000000000001))-N35*SUMPRODUCT($G$7:$G$26,$E$7:$E$26) -> -8.7737884 | P35: =-0.5*((LN(N35)-LN($B$3))/$B$4)^2-LN(N35) -> -0.90456762 | Q35: =O35+P35 -> -9.6783561 | R35: =EXP(Q35-MAX($Q$7:$Q$506)) -> 0.0018996503 | S35: =SUM($R$7:R35)/SUM($R$7:$R$506) -> 5.6275824e-05
A36: Grid search on columns N–S (λ from 0.05 to 5.04 per BU, step 0.01). Extend the grid if the estimate sits at its edge. | N36: =N35+0.01 -> 0.34 | O36: =SUMPRODUCT($F$7:$F$26,LN(1-EXP(-N36*$E$7:$E$26)+0.000000000001))-N36*SUMPRODUCT($G$7:$G$26,$E$7:$E$26) -> -8.6065453 | P36: =-0.5*((LN(N36)-LN($B$3))/$B$4)^2-LN(N36) -> -0.81639682 | Q36: =O36+P36 -> -9.4229421 | R36: =EXP(Q36-MAX($Q$7:$Q$506)) -> 0.0024524408 | S36: =SUM($R$7:R36)/SUM($R$7:$R$506) -> 7.5493122e-05
N37: =N36+0.01 -> 0.35 | O37: =SUMPRODUCT($F$7:$F$26,LN(1-EXP(-N37*$E$7:$E$26)+0.000000000001))-N37*SUMPRODUCT($G$7:$G$26,$E$7:$E$26) -> -8.4452838 | P37: =-0.5*((LN(N37)-LN($B$3))/$B$4)^2-LN(N37) -> -0.73419334 | Q37: =O37+P37 -> -9.1794771 | R37: =EXP(Q37-MAX($Q$7:$Q$506)) -> 0.0031284846 | S37: =SUM($R$7:R37)/SUM($R$7:$R$506) -> 0.00010000789
N38: =N37+0.01 -> 0.36 | O38: =SUMPRODUCT($F$7:$F$26,LN(1-EXP(-N38*$E$7:$E$26)+0.000000000001))-N38*SUMPRODUCT($G$7:$G$26,$E$7:$E$26) -> -8.2896626 | P38: =-0.5*((LN(N38)-LN($B$3))/$B$4)^2-LN(N38) -> -0.65752616 | Q38: =O38+P38 -> -8.9471888 | R38: =EXP(Q38-MAX($Q$7:$Q$506)) -> 0.0039465313 | S38: =SUM($R$7:R38)/SUM($R$7:$R$506) -> 0.00013093287
N39: =N38+0.01 -> 0.37 | O39: =SUMPRODUCT($F$7:$F$26,LN(1-EXP(-N39*$E$7:$E$26)+0.000000000001))-N39*SUMPRODUCT($G$7:$G$26,$E$7:$E$26) -> -8.1393686 | P39: =-0.5*((LN(N39)-LN($B$3))/$B$4)^2-LN(N39) -> -0.58600484 | Q39: =O39+P39 -> -8.7253734 | R39: =EXP(Q39-MAX($Q$7:$Q$506)) -> 0.0049266163 | S39: =SUM($R$7:R39)/SUM($R$7:$R$506) -> 0.00016953778
N40: =N39+0.01 -> 0.38 | O40: =SUMPRODUCT($F$7:$F$26,LN(1-EXP(-N40*$E$7:$E$26)+0.000000000001))-N40*SUMPRODUCT($G$7:$G$26,$E$7:$E$26) -> -7.9941135 | P40: =-0.5*((LN(N40)-LN($B$3))/$B$4)^2-LN(N40) -> -0.51927474 | Q40: =O40+P40 -> -8.5133882 | R40: =EXP(Q40-MAX($Q$7:$Q$506)) -> 0.0060899363 | S40: =SUM($R$7:R40)/SUM($R$7:$R$506) -> 0.00021725845
N41: =N40+0.01 -> 0.39 | O41: =SUMPRODUCT($F$7:$F$26,LN(1-EXP(-N41*$E$7:$E$26)+0.000000000001))-N41*SUMPRODUCT($G$7:$G$26,$E$7:$E$26) -> -7.8536316 | P41: =-0.5*((LN(N41)-LN($B$3))/$B$4)^2-LN(N41) -> -0.45701298 | Q41: =O41+P41 -> -8.3106446 | R41: =EXP(Q41-MAX($Q$7:$Q$506)) -> 0.0074587011 | S41: =SUM($R$7:R41)/SUM($R$7:$R$506) -> 0.00027570475
N42: =N41+0.01 -> 0.4 | O42: =SUMPRODUCT($F$7:$F$26,LN(1-EXP(-N42*$E$7:$E$26)+0.000000000001))-N42*SUMPRODUCT($G$7:$G$26,$E$7:$E$26) -> -7.7176774 | P42: =-0.5*((LN(N42)-LN($B$3))/$B$4)^2-LN(N42) -> -0.3989249 | Q42: =O42+P42 -> -8.1166023 | R42: =EXP(Q42-MAX($Q$7:$Q$506)) -> 0.0090559644 | S42: =SUM($R$7:R42)/SUM($R$7:$R$506) -> 0.00034666718
...

Sheet Calib_Rates
A1: Rates and ceilings (S1, Sec. 3.3–3.4)
A3: Separate-effects campaign (engine E-1): K versus cost | H3: Ceiling levels used by the S and T campaigns
A4: cost (BU) | B4: K | C4: ln(gap) | H4: M during the CFD campaign | I4: 0.1
A5: 0 | B5: 0.3 | C5: =IF(B5="","",LN(1-B5)) -> -0.35667494 | E5: r_E (per BU) | F5: =-SLOPE(C5:C12,A5:A12) -> 0.098858629 | H5: K during the ground-test campaign | I5: 0.5
A6: 1 | B6: 0.37 | C6: =IF(B6="","",LN(1-B6)) -> -0.46203546 | H6: K̄ at that M (from the ceiling fit) | I6: =F32+F33*I4 -> 0.464
A7: 2 | B7: 0.43 | C7: =IF(B7="","",LN(1-B7)) -> -0.56211892 | H7: M̄ at that K (from the ceiling fit) | I7: =F42+F43*I5 -> 0.57366667
A8: 3 | B8: 0.48 | C8: =IF(B8="","",LN(1-B8)) -> -0.65392647
A9: 4 | B9: 0.53 | C9: =IF(B9="","",LN(1-B9)) -> -0.75502258 | E9: (ln(1−K) = ln(1−K₀) − r_E·c)
C10: =IF(B10="","",LN(1-B10))
C11: =IF(B11="","",LN(1-B11))
C12: =IF(B12="","",LN(1-B12))
A13: Simulation campaign (CFD): K versus cost
A14: cost (BU) | B14: K | C14: ln(gap)
A15: 0 | B15: 0.2 | C15: =IF(B15="","",LN($I$6-B15)) -> -1.3318062 | E15: r_S (per BU) | F15: =-SLOPE(C15:C22,A15:A22) -> 0.30927195
A16: 1 | B16: 0.27 | C16: =IF(B16="","",LN($I$6-B16)) -> -1.6398971
A17: 2 | B17: 0.32 | C17: =IF(B17="","",LN($I$6-B17)) -> -1.937942
A18: 3 | B18: 0.36 | C18: =IF(B18="","",LN($I$6-B18)) -> -2.2633644
C19: =IF(B19="","",LN($I$6-B19)) | E19: (ln(K̄−K) = ln(K̄−K₀) − r_S·c)
C20: =IF(B20="","",LN($I$6-B20))
C21: =IF(B21="","",LN($I$6-B21))
C22: =IF(B22="","",LN($I$6-B22))
A24: Simulation plateaus: K where S stopped improving, versus demonstrated M
A25: M | B25: plateau K
A26: 0.1 | B26: 0.47
A27: 0.3 | B27: 0.57
A28: 0.5 | B28: 0.71
A29: 0.7 | B29: 0.82
E32: k_b (intercept) | F32: =INTERCEPT(B26:B31,A26:A31) -> 0.4045
E33: k_l (slope) | F33: =SLOPE(B26:B31,A26:A31) -> 0.595
A34: Test plateaus: M where T stopped passing more envelope, versus K
A35: K | B35: plateau M
A36: 0.3 | B36: 0.36
A37: 0.45 | B37: 0.53
A38: 0.6 | B38: 0.67
A39: 0.75 | B39: 0.84
E42: m_b (intercept) | F42: =INTERCEPT(B36:B41,A36:A41) -> 0.047
E43: m_l (slope) | F43: =SLOPE(B36:B41,A36:A41) -> 1.0533333
A46: Integrated campaign (ground tests): M versus cost
A47: cost (BU) | B47: M | C47: ln(gap)
A48: 0 | B48: 0.1 | C48: =IF(B48="","",LN($I$7-B48)) -> -0.74725144 | E48: r_T (per BU) | F48: =-SLOPE(C48:C55,A48:A55) -> 0.23607435
...

Sheet Parameters
A1: Parameter card (paper Table 5 notation)
A3: Symbol | B3: Meaning | C3: Calibrated / default | D3: Override (optional) | E3: Value used
A4: k_b | B4: simulation ceiling, intercept | C4: =Calib_Rates!F32 -> 0.4045 | D4: 0.4 | E4: =IF(D4="",C4,D4) -> 0.4
A5: k_l | B5: simulation ceiling, slope | C5: =Calib_Rates!F33 -> 0.595 | D5: 0.6 | E5: =IF(D5="",C5,D5) -> 0.6
A6: m_b | B6: test ceiling, intercept | C6: =Calib_Rates!F42 -> 0.047 | D6: 0.05 | E6: =IF(D6="",C6,D6) -> 0.05
A7: m_l | B7: test ceiling, slope | C7: =Calib_Rates!F43 -> 1.0533333 | D7: 1.05 | E7: =IF(D7="",C7,D7) -> 1.05
A8: r_S | B8: simulation rate (per BU) | C8: =Calib_Rates!F15 -> 0.30927195 | D8: 0.3 | E8: =IF(D8="",C8,D8) -> 0.3
A9: r_E | B9: separate-effects rate (per BU) | C9: =Calib_Rates!F5 -> 0.098858629 | D9: 0.1 | E9: =IF(D9="",C9,D9) -> 0.1
A10: e_E | B10: separate-effects maturity credit (per BU) | C10: 0.05 | E10: =IF(D10="",C10,D10) -> 0.05
A11: r_T | B11: integrated-test maturity rate (per BU) | C11: =Calib_Rates!F48 -> 0.23607435 | D11: 0.24 | E11: =IF(D11="",C11,D11) -> 0.24
A12: e_T | B12: integrated-test knowledge credit (per BU) | C12: =Calib_Hazard!B34 -> 0.035467777 | D12: 0.035 | E12: =IF(D12="",C12,D12) -> 0.035
A13: λ_E | B13: separate-effects shock hazard scale (per BU) | C13: 0.05 | E13: =IF(D13="",C13,D13) -> 0.05
A14: λ_T | B14: integrated-test shock hazard scale (per BU) | C14: =Calib_Hazard!B31 -> 1.48 | D14: 1.5 | E14: =IF(D14="",C14,D14) -> 1.5
A15: δ_K | B15: K lost in a shock | C15: 0.06 | E15: =IF(D15="",C15,D15) -> 0.06
A16: δ_M | B16: M lost in a shock | C16: 0.15 | E16: =IF(D16="",C16,D16) -> 0.15
A17: ρ | B17: rework per shock (BU) | C17: 2 | E17: =IF(D17="",C17,D17) -> 2
A19: Project and policy
A20: K_req | B20: required knowledge (target region) | E20: 0.75
A21: M_req | B21: required maturity (target region) | E21: 0.8
A22: h_max | B22: exposure limit: λ_T(1−K)² per BU | E22: 0.05
A23: c_f | B23: cost of one integrated test (BU) | E23: 2
A24: Budget | B24: program budget (BU) | E24: 30
A26: Thresholds (S1, Sec. 4.2)
A27: K_need | B27: knowledge for which M̄(K) reaches M_req | E27: =MIN(1,MAX(0,(E21-E6)/E7)) -> 0.71428571
A28: K_haz | B28: knowledge for which the test hazard is within h_max | E28: =MIN(1,MAX(0,1-SQRT(E22/E14))) -> 0.81742581
A29: K_test | B29: test threshold = max(K_need, K_haz) | E29: =MAX(E27,E28) -> 0.81742581
A30: P(lose one test) at K_test | B30: 1 − exp(−h_max·c_f) at the threshold | E30: =1-EXP(-E14*(1-E29)^2*E23) -> 0.095162582

Sheet Decision
A1: Decision at each review — headroom procedure (Table 6, steps 3–4)
A2: Enter date, cumulative cost, K and M after each review (yellow). Example rows: Project N of S1, Sec. 4.4.
A4: Review | B4: Cum. cost (BU) | C4: K | D4: M | E4: K̄(M) | F4: M̄(K) | G4: S: K gain | H4: E: K gain | I4: T: K gain | J4: E: hazard | K4: T: hazard | L4: net S | M4: net E | N4: net T | O4: Step | P4: Recommended activity | Q4: P(lose a test now) | R4: Budget left (BU)
A5: R0 | B5: 0 | C5: 0.2 | D5: 0.1 | E5: =IF(C5="","",MIN(1,Parameters!$E$4+Parameters!$E$5*D5)) -> 0.46 | F5: =IF(C5="","",MIN(1,Parameters!$E$6+Parameters!$E$7*C5)) -> 0.26 | G5: =IF(C5="","",Parameters!$E$8*MAX(E5-C5,0)) -> 0.078 | H5: =IF(C5="","",Parameters!$E$9*(1-C5)) -> 0.08 | I5: =IF(C5="","",Parameters!$E$12*(1-C5)) -> 0.028 | J5: =IF(C5="","",Parameters!$E$13*(1-C5)^2) -> 0.032 | K5: =IF(C5="","",Parameters!$E$14*(1-C5)^2) -> 0.96 | L5: =IF(C5="","",G5) -> 0.078 | M5: =IF(C5="","",H5-J5*Parameters!$E$15) -> 0.07808 | N5: =IF(C5="","",I5-K5*Parameters!$E$15) -> -0.0296 | O5: =IF(C5="","",IF(AND(C5>=Parameters!$E$20,D5>=Parameters!$E$21),"done",IF(AND(D5<Parameters!$E$21,C5>=Parameters!$E$27,K5<=Parameters!$E$22),"3",IF(AND(C5>=Parameters!$E$20,C5>=Parameters!$E$27,K5<=Parameters!$E$22),"3",IF(AND(C5>=Parameters!$E$27,K5>Parameters!$E$22),"3b/4","4"))))) -> 4 | P5: =IF(C5="","",IF(O5="done","Target region reached: decision checkpoint",IF(O5="3","T integrated test",IF(MAX(L5:N5)=L5,"S simulation / analysis",IF(MAX(L5:N5)=M5,"E separate-effects test","T integrated test (to learn)"))))) -> E separate-effects test | Q5: =IF(C5="","",1-EXP(-K5*Parameters!$E$23)) -> 0.85339304 | R5: =IF(B5="","",Parameters!$E$24-B5) -> 30
A6: R1 | B6: 4 | C6: 0.465 | D6: 0.156 | E6: =IF(C6="","",MIN(1,Parameters!$E$4+Parameters!$E$5*D6)) -> 0.4936 | F6: =IF(C6="","",MIN(1,Parameters!$E$6+Parameters!$E$7*C6)) -> 0.53825 | G6: =IF(C6="","",Parameters!$E$8*MAX(E6-C6,0)) -> 0.00858 | H6: =IF(C6="","",Parameters!$E$9*(1-C6)) -> 0.0535 | I6: =IF(C6="","",Parameters!$E$12*(1-C6)) -> 0.018725 | J6: =IF(C6="","",Parameters!$E$13*(1-C6)^2) -> 0.01431125 | K6: =IF(C6="","",Parameters!$E$14*(1-C6)^2) -> 0.4293375 | L6: =IF(C6="","",G6) -> 0.00858 | M6: =IF(C6="","",H6-J6*Parameters!$E$15) -> 0.052641325 | N6: =IF(C6="","",I6-K6*Parameters!$E$15) -> -0.00703525 | O6: =IF(C6="","",IF(AND(C6>=Parameters!$E$20,D6>=Parameters!$E$21),"done",IF(AND(D6<Parameters!$E$21,C6>=Parameters!$E$27,K6<=Parameters!$E$22),"3",IF(AND(C6>=Parameters!$E$20,C6>=Parameters!$E$27,K6<=Parameters!$E$22),"3",IF(AND(C6>=Parameters!$E$27,K6>Parameters!$E$22),"3b/4","4"))))) -> 4 | P6: =IF(C6="","",IF(O6="done","Target region reached: decision checkpoint",IF(O6="3","T integrated test",IF(MAX(L6:N6)=L6,"S simulation / analysis",IF(MAX(L6:N6)=M6,"E separate-effects test","T integrated test (to learn)"))))) -> E separate-effects test | Q6: =IF(C6="","",1-EXP(-K6*Parameters!$E$23)) -> 0.57627686 | R6: =IF(B6="","",Parameters!$E$24-B6) -> 26
A7: R2 | B7: 8 | C7: 0.642 | D7: 0.244 | E7: =IF(C7="","",MIN(1,Parameters!$E$4+Parameters!$E$5*D7)) -> 0.5464 | F7: =IF(C7="","",MIN(1,Parameters!$E$6+Parameters!$E$7*C7)) -> 0.7241 | G7: =IF(C7="","",Parameters!$E$8*MAX(E7-C7,0)) -> 0 | H7: =IF(C7="","",Parameters!$E$9*(1-C7)) -> 0.0358 | I7: =IF(C7="","",Parameters!$E$12*(1-C7)) -> 0.01253 | J7: =IF(C7="","",Parameters!$E$13*(1-C7)^2) -> 0.0064082 | K7: =IF(C7="","",Parameters!$E$14*(1-C7)^2) -> 0.192246 | L7: =IF(C7="","",G7) -> 0 | M7: =IF(C7="","",H7-J7*Parameters!$E$15) -> 0.035415508 | N7: =IF(C7="","",I7-K7*Parameters!$E$15) -> 0.00099524 | O7: =IF(C7="","",IF(AND(C7>=Parameters!$E$20,D7>=Parameters!$E$21),"done",IF(AND(D7<Parameters!$E$21,C7>=Parameters!$E$27,K7<=Parameters!$E$22),"3",IF(AND(C7>=Parameters!$E$20,C7>=Parameters!$E$27,K7<=Parameters!$E$22),"3",IF(AND(C7>=Parameters!$E$27,K7>Parameters!$E$22),"3b/4","4"))))) -> 4 | P7: =IF(C7="","",IF(O7="done","Target region reached: decision checkpoint",IF(O7="3","T integrated test",IF(MAX(L7:N7)=L7,"S simulation / analysis",IF(MAX(L7:N7)=M7,"E separate-effects test","T integrated test (to learn)"))))) -> E separate-effects test | Q7: =IF(C7="","",1-EXP(-K7*Parameters!$E$23)) -> 0.31920361 | R7: =IF(B7="","",Parameters!$E$24-B7) -> 22
A8: R3 | B8: 12 | C8: 0.76 | D8: 0.343 | E8: =IF(C8="","",MIN(1,Parameters!$E$4+Parameters!$E$5*D8)) -> 0.6058 | F8: =IF(C8="","",MIN(1,Parameters!$E$6+Parameters!$E$7*C8)) -> 0.848 | G8: =IF(C8="","",Parameters!$E$8*MAX(E8-C8,0)) -> 0 | H8: =IF(C8="","",Parameters!$E$9*(1-C8)) -> 0.024 | I8: =IF(C8="","",Parameters!$E$12*(1-C8)) -> 0.0084 | J8: =IF(C8="","",Parameters!$E$13*(1-C8)^2) -> 0.00288 | K8: =IF(C8="","",Parameters!$E$14*(1-C8)^2) -> 0.0864 | L8: =IF(C8="","",G8) -> 0 | M8: =IF(C8="","",H8-J8*Parameters!$E$15) -> 0.0238272 | N8: =IF(C8="","",I8-K8*Parameters!$E$15) -> 0.003216 | O8: =IF(C8="","",IF(AND(C8>=Parameters!$E$20,D8>=Parameters!$E$21),"done",IF(AND(D8<Parameters!$E$21,C8>=Parameters!$E$27,K8<=Parameters!$E$22),"3",IF(AND(C8>=Parameters!$E$20,C8>=Parameters!$E$27,K8<=Parameters!$E$22),"3",IF(AND(C8>=Parameters!$E$27,K8>Parameters!$E$22),"3b/4","4"))))) -> 3b/4 | P8: =IF(C8="","",IF(O8="done","Target region reached: decision checkpoint",IF(O8="3","T integrated test",IF(MAX(L8:N8)=L8,"S simulation / analysis",IF(MAX(L8:N8)=M8,"E separate-effects test","T integrated test (to learn)"))))) -> E separate-effects test | Q8: =IF(C8="","",1-EXP(-K8*Parameters!$E$23)) -> 0.15869414 | R8: =IF(B8="","",Parameters!$E$24-B8) -> 18
A9: R4 | B9: 14.8 | C9: 0.819 | D9: 0.414 | E9: =IF(C9="","",MIN(1,Parameters!$E$4+Parameters!$E$5*D9)) -> 0.6484 | F9: =IF(C9="","",MIN(1,Parameters!$E$6+Parameters!$E$7*C9)) -> 0.90995 | G9: =IF(C9="","",Parameters!$E$8*MAX(E9-C9,0)) -> 0 | H9: =IF(C9="","",Parameters!$E$9*(1-C9)) -> 0.0181 | I9: =IF(C9="","",Parameters!$E$12*(1-C9)) -> 0.006335 | J9: =IF(C9="","",Parameters!$E$13*(1-C9)^2) -> 0.00163805 | K9: =IF(C9="","",Parameters!$E$14*(1-C9)^2) -> 0.0491415 | L9: =IF(C9="","",G9) -> 0 | M9: =IF(C9="","",H9-J9*Parameters!$E$15) -> 0.018001717 | N9: =IF(C9="","",I9-K9*Parameters!$E$15) -> 0.00338651 | O9: =IF(C9="","",IF(AND(C9>=Parameters!$E$20,D9>=Parameters!$E$21),"done",IF(AND(D9<Parameters!$E$21,C9>=Parameters!$E$27,K9<=Parameters!$E$22),"3",IF(AND(C9>=Parameters!$E$20,C9>=Parameters!$E$27,K9<=Parameters!$E$22),"3",IF(AND(C9>=Parameters!$E$27,K9>Parameters!$E$22),"3b/4","4"))))) -> 3 | P9: =IF(C9="","",IF(O9="done","Target region reached: decision checkpoint",IF(O9="3","T integrated test",IF(MAX(L9:N9)=L9,"S simulation / analysis",IF(MAX(L9:N9)=M9,"E separate-effects test","T integrated test (to learn)"))))) -> T integrated test | Q9: =IF(C9="","",1-EXP(-K9*Parameters!$E$23)) -> 0.093607642 | R9: =IF(B9="","",Parameters!$E$24-B9) -> 15.2
A10: R5 | B10: 18 | C10: 0.838 | D10: 0.688 | E10: =IF(C10="","",MIN(1,Parameters!$E$4+Parameters!$E$5*D10)) -> 0.8128 | F10: =IF(C10="","",MIN(1,Parameters!$E$6+Parameters!$E$7*C10)) -> 0.9299 | G10: =IF(C10="","",Parameters!$E$8*MAX(E10-C10,0)) -> 0 | H10: =IF(C10="","",Parameters!$E$9*(1-C10)) -> 0.0162 | I10: =IF(C10="","",Parameters!$E$12*(1-C10)) -> 0.00567 | J10: =IF(C10="","",Parameters!$E$13*(1-C10)^2) -> 0.0013122 | K10: =IF(C10="","",Parameters!$E$14*(1-C10)^2) -> 0.039366 | L10: =IF(C10="","",G10) -> 0 | M10: =IF(C10="","",H10-J10*Parameters!$E$15) -> 0.016121268 | N10: =IF(C10="","",I10-K10*Parameters!$E$15) -> 0.00330804 | O10: =IF(C10="","",IF(AND(C10>=Parameters!$E$20,D10>=Parameters!$E$21),"done",IF(AND(D10<Parameters!$E$21,C10>=Parameters!$E$27,K10<=Parameters!$E$22),"3",IF(AND(C10>=Parameters!$E$20,C10>=Parameters!$E$27,K10<=Parameters!$E$22),"3",IF(AND(C10>=Parameters!$E$27,K10>Parameters!$E$22),"3b/4","4"))))) -> 3 | P10: =IF(C10="","",IF(O10="done","Target region reached: decision checkpoint",IF(O10="3","T integrated test",IF(MAX(L10:N10)=L10,"S simulation / analysis",IF(MAX(L10:N10)=M10,"E separate-effects test","T integrated test (to learn)"))))) -> T integrated test | Q10: =IF(C10="","",1-EXP(-K10*Parameters!$E$23)) -> 0.0757124 | R10: =IF(B10="","",Parameters!$E$24-B10) -> 12
A11: R6 | B11: 20.4 | C11: 0.85 | D11: 0.8 | E11: =IF(C11="","",MIN(1,Parameters!$E$4+Parameters!$E$5*D11)) -> 0.88 | F11: =IF(C11="","",MIN(1,Parameters!$E$6+Parameters!$E$7*C11)) -> 0.9425 | G11: =IF(C11="","",Parameters!$E$8*MAX(E11-C11,0)) -> 0.009 | H11: =IF(C11="","",Parameters!$E$9*(1-C11)) -> 0.015 | I11: =IF(C11="","",Parameters!$E$12*(1-C11)) -> 0.00525 | J11: =IF(C11="","",Parameters!$E$13*(1-C11)^2) -> 0.001125 | K11: =IF(C11="","",Parameters!$E$14*(1-C11)^2) -> 0.03375 | L11: =IF(C11="","",G11) -> 0.009 | M11: =IF(C11="","",H11-J11*Parameters!$E$15) -> 0.0149325 | N11: =IF(C11="","",I11-K11*Parameters!$E$15) -> 0.003225 | O11: =IF(C11="","",IF(AND(C11>=Parameters!$E$20,D11>=Parameters!$E$21),"done",IF(AND(D11<Parameters!$E$21,C11>=Parameters!$E$27,K11<=Parameters!$E$22),"3",IF(AND(C11>=Parameters!$E$20,C11>=Parameters!$E$27,K11<=Parameters!$E$22),"3",IF(AND(C11>=Parameters!$E$27,K11>Parameters!$E$22),"3b/4","4"))))) -> done | P11: =IF(C11="","",IF(O11="done","Target region reached: decision checkpoint",IF(O11="3","T integrated test",IF(MAX(L11:N11)=L11,"S simulation / analysis",IF(MAX(L11:N11)=M11,"E separate-effects test","T integrated test (to learn)"))))) -> Target region reached: decision checkpoint | Q11: =IF(C11="","",1-EXP(-K11*Parameters!$E$23)) -> 0.065272279 | R11: =IF(B11="","",Parameters!$E$24-B11) -> 9.6
E12: =IF(C12="","",MIN(1,Parameters!$E$4+Parameters!$E$5*D12)) | F12: =IF(C12="","",MIN(1,Parameters!$E$6+Parameters!$E$7*C12)) | G12: =IF(C12="","",Parameters!$E$8*MAX(E12-C12,0)) | H12: =IF(C12="","",Parameters!$E$9*(1-C12)) | I12: =IF(C12="","",Parameters!$E$12*(1-C12)) | J12: =IF(C12="","",Parameters!$E$13*(1-C12)^2) | K12: =IF(C12="","",Parameters!$E$14*(1-C12)^2) | L12: =IF(C12="","",G12) | M12: =IF(C12="","",H12-J12*Parameters!$E$15) | N12: =IF(C12="","",I12-K12*Parameters!$E$15) | O12: =IF(C12="","",IF(AND(C12>=Parameters!$E$20,D12>=Parameters!$E$21),"done",IF(AND(D12<Parameters!$E$21,C12>=Parameters!$E$27,K12<=Parameters!$E$22),"3",IF(AND(C12>=Parameters!$E$20,C12>=Parameters!$E$27,K12<=Parameters!$E$22),"3",IF(AND(C12>=Parameters!$E$27,K12>Parameters!$E$22),"3b/4","4"))))) | P12: =IF(C12="","",IF(O12="done","Target region reached: decision checkpoint",IF(O12="3","T integrated test",IF(MAX(L12:N12)=L12,"S simulation / analysis",IF(MAX(L12:N12)=M12,"E separate-effects test","T integrated test (to learn)"))))) | Q12: =IF(C12="","",1-EXP(-K12*Parameters!$E$23)) | R12: =IF(B12="","",Parameters!$E$24-B12)
E13: =IF(C13="","",MIN(1,Parameters!$E$4+Parameters!$E$5*D13)) | F13: =IF(C13="","",MIN(1,Parameters!$E$6+Parameters!$E$7*C13)) | G13: =IF(C13="","",Parameters!$E$8*MAX(E13-C13,0)) | H13: =IF(C13="","",Parameters!$E$9*(1-C13)) | I13: =IF(C13="","",Parameters!$E$12*(1-C13)) | J13: =IF(C13="","",Parameters!$E$13*(1-C13)^2) | K13: =IF(C13="","",Parameters!$E$14*(1-C13)^2) | L13: =IF(C13="","",G13) | M13: =IF(C13="","",H13-J13*Parameters!$E$15) | N13: =IF(C13="","",I13-K13*Parameters!$E$15) | O13: =IF(C13="","",IF(AND(C13>=Parameters!$E$20,D13>=Parameters!$E$21),"done",IF(AND(D13<Parameters!$E$21,C13>=Parameters!$E$27,K13<=Parameters!$E$22),"3",IF(AND(C13>=Parameters!$E$20,C13>=Parameters!$E$27,K13<=Parameters!$E$22),"3",IF(AND(C13>=Parameters!$E$27,K13>Parameters!$E$22),"3b/4","4"))))) | P13: =IF(C13="","",IF(O13="done","Target region reached: decision checkpoint",IF(O13="3","T integrated test",IF(MAX(L13:N13)=L13,"S simulation / analysis",IF(MAX(L13:N13)=M13,"E separate-effects test","T integrated test (to learn)"))))) | Q13: =IF(C13="","",1-EXP(-K13*Parameters!$E$23)) | R13: =IF(B13="","",Parameters!$E$24-B13)
E14: =IF(C14="","",MIN(1,Parameters!$E$4+Parameters!$E$5*D14)) | F14: =IF(C14="","",MIN(1,Parameters!$E$6+Parameters!$E$7*C14)) | G14: =IF(C14="","",Parameters!$E$8*MAX(E14-C14,0)) | H14: =IF(C14="","",Parameters!$E$9*(1-C14)) | I14: =IF(C14="","",Parameters!$E$12*(1-C14)) | J14: =IF(C14="","",Parameters!$E$13*(1-C14)^2) | K14: =IF(C14="","",Parameters!$E$14*(1-C14)^2) | L14: =IF(C14="","",G14) | M14: =IF(C14="","",H14-J14*Parameters!$E$15) | N14: =IF(C14="","",I14-K14*Parameters!$E$15) | O14: =IF(C14="","",IF(AND(C14>=Parameters!$E$20,D14>=Parameters!$E$21),"done",IF(AND(D14<Parameters!$E$21,C14>=Parameters!$E$27,K14<=Parameters!$E$22),"3",IF(AND(C14>=Parameters!$E$20,C14>=Parameters!$E$27,K14<=Parameters!$E$22),"3",IF(AND(C14>=Parameters!$E$27,K14>Parameters!$E$22),"3b/4","4"))))) | P14: =IF(C14="","",IF(O14="done","Target region reached: decision checkpoint",IF(O14="3","T integrated test",IF(MAX(L14:N14)=L14,"S simulation / analysis",IF(MAX(L14:N14)=M14,"E separate-effects test","T integrated test (to learn)"))))) | Q14: =IF(C14="","",1-EXP(-K14*Parameters!$E$23)) | R14: =IF(B14="","",Parameters!$E$24-B14)
E15: =IF(C15="","",MIN(1,Parameters!$E$4+Parameters!$E$5*D15)) | F15: =IF(C15="","",MIN(1,Parameters!$E$6+Parameters!$E$7*C15)) | G15: =IF(C15="","",Parameters!$E$8*MAX(E15-C15,0)) | H15: =IF(C15="","",Parameters!$E$9*(1-C15)) | I15: =IF(C15="","",Parameters!$E$12*(1-C15)) | J15: =IF(C15="","",Parameters!$E$13*(1-C15)^2) | K15: =IF(C15="","",Parameters!$E$14*(1-C15)^2) | L15: =IF(C15="","",G15) | M15: =IF(C15="","",H15-J15*Parameters!$E$15) | N15: =IF(C15="","",I15-K15*Parameters!$E$15) | O15: =IF(C15="","",IF(AND(C15>=Parameters!$E$20,D15>=Parameters!$E$21),"done",IF(AND(D15<Parameters!$E$21,C15>=Parameters!$E$27,K15<=Parameters!$E$22),"3",IF(AND(C15>=Parameters!$E$20,C15>=Parameters!$E$27,K15<=Parameters!$E$22),"3",IF(AND(C15>=Parameters!$E$27,K15>Parameters!$E$22),"3b/4","4"))))) | P15: =IF(C15="","",IF(O15="done","Target region reached: decision checkpoint",IF(O15="3","T integrated test",IF(MAX(L15:N15)=L15,"S simulation / analysis",IF(MAX(L15:N15)=M15,"E separate-effects test","T integrated test (to learn)"))))) | Q15: =IF(C15="","",1-EXP(-K15*Parameters!$E$23)) | R15: =IF(B15="","",Parameters!$E$24-B15)
E16: =IF(C16="","",MIN(1,Parameters!$E$4+Parameters!$E$5*D16)) | F16: =IF(C16="","",MIN(1,Parameters!$E$6+Parameters!$E$7*C16)) | G16: =IF(C16="","",Parameters!$E$8*MAX(E16-C16,0)) | H16: =IF(C16="","",Parameters!$E$9*(1-C16)) | I16: =IF(C16="","",Parameters!$E$12*(1-C16)) | J16: =IF(C16="","",Parameters!$E$13*(1-C16)^2) | K16: =IF(C16="","",Parameters!$E$14*(1-C16)^2) | L16: =IF(C16="","",G16) | M16: =IF(C16="","",H16-J16*Parameters!$E$15) | N16: =IF(C16="","",I16-K16*Parameters!$E$15) | O16: =IF(C16="","",IF(AND(C16>=Parameters!$E$20,D16>=Parameters!$E$21),"done",IF(AND(D16<Parameters!$E$21,C16>=Parameters!$E$27,K16<=Parameters!$E$22),"3",IF(AND(C16>=Parameters!$E$20,C16>=Parameters!$E$27,K16<=Parameters!$E$22),"3",IF(AND(C16>=Parameters!$E$27,K16>Parameters!$E$22),"3b/4","4"))))) | P16: =IF(C16="","",IF(O16="done","Target region reached: decision checkpoint",IF(O16="3","T integrated test",IF(MAX(L16:N16)=L16,"S simulation / analysis",IF(MAX(L16:N16)=M16,"E separate-effects test","T integrated test (to learn)"))))) | Q16: =IF(C16="","",1-EXP(-K16*Parameters!$E$23)) | R16: =IF(B16="","",Parameters!$E$24-B16)
E17: =IF(C17="","",MIN(1,Parameters!$E$4+Parameters!$E$5*D17)) | F17: =IF(C17="","",MIN(1,Parameters!$E$6+Parameters!$E$7*C17)) | G17: =IF(C17="","",Parameters!$E$8*MAX(E17-C17,0)) | H17: =IF(C17="","",Parameters!$E$9*(1-C17)) | I17: =IF(C17="","",Parameters!$E$12*(1-C17)) | J17: =IF(C17="","",Parameters!$E$13*(1-C17)^2) | K17: =IF(C17="","",Parameters!$E$14*(1-C17)^2) | L17: =IF(C17="","",G17) | M17: =IF(C17="","",H17-J17*Parameters!$E$15) | N17: =IF(C17="","",I17-K17*Parameters!$E$15) | O17: =IF(C17="","",IF(AND(C17>=Parameters!$E$20,D17>=Parameters!$E$21),"done",IF(AND(D17<Parameters!$E$21,C17>=Parameters!$E$27,K17<=Parameters!$E$22),"3",IF(AND(C17>=Parameters!$E$20,C17>=Parameters!$E$27,K17<=Parameters!$E$22),"3",IF(AND(C17>=Parameters!$E$27,K17>Parameters!$E$22),"3b/4","4"))))) | P17: =IF(C17="","",IF(O17="done","Target region reached: decision checkpoint",IF(O17="3","T integrated test",IF(MAX(L17:N17)=L17,"S simulation / analysis",IF(MAX(L17:N17)=M17,"E separate-effects test","T integrated test (to learn)"))))) | Q17: =IF(C17="","",1-EXP(-K17*Parameters!$E$23)) | R17: =IF(B17="","",Parameters!$E$24-B17)
E18: =IF(C18="","",MIN(1,Parameters!$E$4+Parameters!$E$5*D18)) | F18: =IF(C18="","",MIN(1,Parameters!$E$6+Parameters!$E$7*C18)) | G18: =IF(C18="","",Parameters!$E$8*MAX(E18-C18,0)) | H18: =IF(C18="","",Parameters!$E$9*(1-C18)) | I18: =IF(C18="","",Parameters!$E$12*(1-C18)) | J18: =IF(C18="","",Parameters!$E$13*(1-C18)^2) | K18: =IF(C18="","",Parameters!$E$14*(1-C18)^2) | L18: =IF(C18="","",G18) | M18: =IF(C18="","",H18-J18*Parameters!$E$15) | N18: =IF(C18="","",I18-K18*Parameters!$E$15) | O18: =IF(C18="","",IF(AND(C18>=Parameters!$E$20,D18>=Parameters!$E$21),"done",IF(AND(D18<Parameters!$E$21,C18>=Parameters!$E$27,K18<=Parameters!$E$22),"3",IF(AND(C18>=Parameters!$E$20,C18>=Parameters!$E$27,K18<=Parameters!$E$22),"3",IF(AND(C18>=Parameters!$E$27,K18>Parameters!$E$22),"3b/4","4"))))) | P18: =IF(C18="","",IF(O18="done","Target region reached: decision checkpoint",IF(O18="3","T integrated test",IF(MAX(L18:N18)=L18,"S simulation / analysis",IF(MAX(L18:N18)=M18,"E separate-effects test","T integrated test (to learn)"))))) | Q18: =IF(C18="","",1-EXP(-K18*Parameters!$E$23)) | R18: =IF(B18="","",Parameters!$E$24-B18)
E19: =IF(C19="","",MIN(1,Parameters!$E$4+Parameters!$E$5*D19)) | F19: =IF(C19="","",MIN(1,Parameters!$E$6+Parameters!$E$7*C19)) | G19: =IF(C19="","",Parameters!$E$8*MAX(E19-C19,0)) | H19: =IF(C19="","",Parameters!$E$9*(1-C19)) | I19: =IF(C19="","",Parameters!$E$12*(1-C19)) | J19: =IF(C19="","",Parameters!$E$13*(1-C19)^2) | K19: =IF(C19="","",Parameters!$E$14*(1-C19)^2) | L19: =IF(C19="","",G19) | M19: =IF(C19="","",H19-J19*Parameters!$E$15) | N19: =IF(C19="","",I19-K19*Parameters!$E$15) | O19: =IF(C19="","",IF(AND(C19>=Parameters!$E$20,D19>=Parameters!$E$21),"done",IF(AND(D19<Parameters!$E$21,C19>=Parameters!$E$27,K19<=Parameters!$E$22),"3",IF(AND(C19>=Parameters!$E$20,C19>=Parameters!$E$27,K19<=Parameters!$E$22),"3",IF(AND(C19>=Parameters!$E$27,K19>Parameters!$E$22),"3b/4","4"))))) | P19: =IF(C19="","",IF(O19="done","Target region reached: decision checkpoint",IF(O19="3","T integrated test",IF(MAX(L19:N19)=L19,"S simulation / analysis",IF(MAX(L19:N19)=M19,"E separate-effects test","T integrated test (to learn)"))))) | Q19: =IF(C19="","",1-EXP(-K19*Parameters!$E$23)) | R19: =IF(B19="","",Parameters!$E$24-B19)
E20: =IF(C20="","",MIN(1,Parameters!$E$4+Parameters!$E$5*D20)) | F20: =IF(C20="","",MIN(1,Parameters!$E$6+Parameters!$E$7*C20)) | G20: =IF(C20="","",Parameters!$E$8*MAX(E20-C20,0)) | H20: =IF(C20="","",Parameters!$E$9*(1-C20)) | I20: =IF(C20="","",Parameters!$E$12*(1-C20)) | J20: =IF(C20="","",Parameters!$E$13*(1-C20)^2) | K20: =IF(C20="","",Parameters!$E$14*(1-C20)^2) | L20: =IF(C20="","",G20) | M20: =IF(C20="","",H20-J20*Parameters!$E$15) | N20: =IF(C20="","",I20-K20*Parameters!$E$15) | O20: =IF(C20="","",IF(AND(C20>=Parameters!$E$20,D20>=Parameters!$E$21),"done",IF(AND(D20<Parameters!$E$21,C20>=Parameters!$E$27,K20<=Parameters!$E$22),"3",IF(AND(C20>=Parameters!$E$20,C20>=Parameters!$E$27,K20<=Parameters!$E$22),"3",IF(AND(C20>=Parameters!$E$27,K20>Parameters!$E$22),"3b/4","4"))))) | P20: =IF(C20="","",IF(O20="done","Target region reached: decision checkpoint",IF(O20="3","T integrated test",IF(MAX(L20:N20)=L20,"S simulation / analysis",IF(MAX(L20:N20)=M20,"E separate-effects test","T integrated test (to learn)"))))) | Q20: =IF(C20="","",1-EXP(-K20*Parameters!$E$23)) | R20: =IF(B20="","",Parameters!$E$24-B20)
E21: =IF(C21="","",MIN(1,Parameters!$E$4+Parameters!$E$5*D21)) | F21: =IF(C21="","",MIN(1,Parameters!$E$6+Parameters!$E$7*C21)) | G21: =IF(C21="","",Parameters!$E$8*MAX(E21-C21,0)) | H21: =IF(C21="","",Parameters!$E$9*(1-C21)) | I21: =IF(C21="","",Parameters!$E$12*(1-C21)) | J21: =IF(C21="","",Parameters!$E$13*(1-C21)^2) | K21: =IF(C21="","",Parameters!$E$14*(1-C21)^2) | L21: =IF(C21="","",G21) | M21: =IF(C21="","",H21-J21*Parameters!$E$15) | N21: =IF(C21="","",I21-K21*Parameters!$E$15) | O21: =IF(C21="","",IF(AND(C21>=Parameters!$E$20,D21>=Parameters!$E$21),"done",IF(AND(D21<Parameters!$E$21,C21>=Parameters!$E$27,K21<=Parameters!$E$22),"3",IF(AND(C21>=Parameters!$E$20,C21>=Parameters!$E$27,K21<=Parameters!$E$22),"3",IF(AND(C21>=Parameters!$E$27,K21>Parameters!$E$22),"3b/4","4"))))) | P21: =IF(C21="","",IF(O21="done","Target region reached: decision checkpoint",IF(O21="3","T integrated test",IF(MAX(L21:N21)=L21,"S simulation / analysis",IF(MAX(L21:N21)=M21,"E separate-effects test","T integrated test (to learn)"))))) | Q21: =IF(C21="","",1-EXP(-K21*Parameters!$E$23)) | R21: =IF(B21="","",Parameters!$E$24-B21)
E22: =IF(C22="","",MIN(1,Parameters!$E$4+Parameters!$E$5*D22)) | F22: =IF(C22="","",MIN(1,Parameters!$E$6+Parameters!$E$7*C22)) | G22: =IF(C22="","",Parameters!$E$8*MAX(E22-C22,0)) | H22: =IF(C22="","",Parameters!$E$9*(1-C22)) | I22: =IF(C22="","",Parameters!$E$12*(1-C22)) | J22: =IF(C22="","",Parameters!$E$13*(1-C22)^2) | K22: =IF(C22="","",Parameters!$E$14*(1-C22)^2) | L22: =IF(C22="","",G22) | M22: =IF(C22="","",H22-J22*Parameters!$E$15) | N22: =IF(C22="","",I22-K22*Parameters!$E$15) | O22: =IF(C22="","",IF(AND(C22>=Parameters!$E$20,D22>=Parameters!$E$21),"done",IF(AND(D22<Parameters!$E$21,C22>=Parameters!$E$27,K22<=Parameters!$E$22),"3",IF(AND(C22>=Parameters!$E$20,C22>=Parameters!$E$27,K22<=Parameters!$E$22),"3",IF(AND(C22>=Parameters!$E$27,K22>Parameters!$E$22),"3b/4","4"))))) | P22: =IF(C22="","",IF(O22="done","Target region reached: decision checkpoint",IF(O22="3","T integrated test",IF(MAX(L22:N22)=L22,"S simulation / analysis",IF(MAX(L22:N22)=M22,"E separate-effects test","T integrated test (to learn)"))))) | Q22: =IF(C22="","",1-EXP(-K22*Parameters!$E$23)) | R22: =IF(B22="","",Parameters!$E$24-B22)
E23: =IF(C23="","",MIN(1,Parameters!$E$4+Parameters!$E$5*D23)) | F23: =IF(C23="","",MIN(1,Parameters!$E$6+Parameters!$E$7*C23)) | G23: =IF(C23="","",Parameters!$E$8*MAX(E23-C23,0)) | H23: =IF(C23="","",Parameters!$E$9*(1-C23)) | I23: =IF(C23="","",Parameters!$E$12*(1-C23)) | J23: =IF(C23="","",Parameters!$E$13*(1-C23)^2) | K23: =IF(C23="","",Parameters!$E$14*(1-C23)^2) | L23: =IF(C23="","",G23) | M23: =IF(C23="","",H23-J23*Parameters!$E$15) | N23: =IF(C23="","",I23-K23*Parameters!$E$15) | O23: =IF(C23="","",IF(AND(C23>=Parameters!$E$20,D23>=Parameters!$E$21),"done",IF(AND(D23<Parameters!$E$21,C23>=Parameters!$E$27,K23<=Parameters!$E$22),"3",IF(AND(C23>=Parameters!$E$20,C23>=Parameters!$E$27,K23<=Parameters!$E$22),"3",IF(AND(C23>=Parameters!$E$27,K23>Parameters!$E$22),"3b/4","4"))))) | P23: =IF(C23="","",IF(O23="done","Target region reached: decision checkpoint",IF(O23="3","T integrated test",IF(MAX(L23:N23)=L23,"S simulation / analysis",IF(MAX(L23:N23)=M23,"E separate-effects test","T integrated test (to learn)"))))) | Q23: =IF(C23="","",1-EXP(-K23*Parameters!$E$23)) | R23: =IF(B23="","",Parameters!$E$24-B23)
... E34: =IF(C34="","",MIN(1,Parameters!$E$4+Parameters!$E$5*D34)) | F34: =IF(C34="","",MIN(1,Parameters!$E$6+Parameters!$E$7*C34)) | G34: =IF(C34="","",Parameters!$E$8*MAX(E34-C34,0)) | H34: =IF(C34="","",Parameters!$E$9*(1-C34)) | I34: =IF(C34="","",Parameters!$E$12*(1-C34)) | J34: =IF(C34="","",Parameters!$E$13*(1-C34)^2) | K34: =IF(C34="","",Parameters!$E$14*(1-C34)^2) | L34: =IF(C34="","",G34) | M34: =IF(C34="","",H34-J34*Parameters!$E$15) | N34: =IF(C34="","",I34-K34*Parameters!$E$15) | O34: =IF(C34="","",IF(AND(C34>=Parameters!$E$20,D34>=Parameters!$E$21),"done",IF(AND(D34<Parameters!$E$21,C34>=Parameters!$E$27,K34<=Parameters!$E$22),"3",IF(AND(C34>=Parameters!$E$20,C34>=Parameters!$E$27,K34<=Parameters!$E$22),"3",IF(AND(C34>=Parameters!$E$27,K34>Parameters!$E$22),"3b/4","4"))))) | P34: =IF(C34="","",IF(O34="done","Target region reached: decision checkpoint",IF(O34="3","T integrated test",IF(MAX(L34:N34)=L34,"S simulation / analysis",IF(MAX(L34:N34)=M34,"E separate-effects test","T integrated test (to learn)"))))) | Q34: =IF(C34="","",1-EXP(-K34*Parameters!$E$23)) | R34: =IF(B34="","",Parameters!$E$24-B34)
A37: Step 0 first: screen every candidate activity against cost, schedule and exposure and keep only the admissible ones. Step 3: M < M_req, K ≥ K_need and hazard ≤ h_max → integrated test. Step 4 (and 3b): otherwise the admissible activity with the largest net K rate = K gain − hazard·δ_K. Re-assess after every result.
